Workbook

Sheet NOTE
B2: VT_Model_DMD_02 - domanda finale con separazione elettrico / non elettrico
B4: Perche: nel run precedente i profili orari erano imposti con FLO_FR sui processi ELE_DMD_*.
B5: Ogni vincolo FLO_FR lega il flusso di un'ora alla somma dei flussi di tutte le 2016 timeslice: righe dense,
B6: circa 12 milioni di non-zeri su 17,3 totali, che hanno saturato la memoria di CPLEX su NEOS.
B8: Cosa cambia rispetto a VT_Model_DMD_01_C2:
B9: 1) Ogni settore ha due domande: DEM_ELC_<sett> (elettrica, livello DAYNITE) e DEM_FUEL_<sett> (non elettrica, ANNUAL).
B10: 2) Domanda elettrica = domanda totale x quota elettrica (Share-I di ELEC_LV_DIST del file C2), calcolata nel foglio DEMAND.
B11: 3) Domanda non elettrica = domanda totale x (somma quote non elettriche).
B12: 4) I processi DMD_FUEL_<sett> usano le quote dei combustibili rinormalizzate sulla sola parte non elettrica (foglio FINAL_DEMAND_PRC).
B13: 5) Il profilo orario si applica con COM_FR sulle DEM_ELC_* (file Scen_COM_FR_ELC_DEM.xlsx): entra come termine noto,
B14: non crea righe dense e, avendo interpolazione STD, vale per tutti i periodi 2023-2050.
B15: 6) I processi non elettrici sono ANNUAL: non generano piu vincoli per ognuna delle 2016 timeslice.
... B22: Scen_COM_FR_ELE_*.xlsx da SuppXLS; aggiungere questo file e Scen_COM_FR_ELC_DEM.xlsx; risincronizzare.

Sheet INPUT
B2: Dati di partenza (da VT_Model_DMD_01_C2)
B3: Nessun tag VEDA in questo foglio: non viene letto dal modello. Celle in blu = input.
B4: Domanda finale totale [PJ/a]
B5: Settore | C5: 2023 | D5: 2025 | E5: 2030 | F5: 2035 | G5: 2040 | H5: 2045 | I5: 2050
B6: RES | C6: 14.385823 | D6: 13.740241 | E6: 13.488018 | F6: 13.611994 | G6: 14.60541 | H6: 16.129687 | I6: 17.653963
B7: IND | C7: 23.436112 | D7: 24.547544 | E7: 26.407019 | F7: 28.266494 | G7: 30.499897 | H7: 35.82674 | I7: 41.630361
B8: SER | C8: 9.952162 | D8: 10.136709 | E8: 11.047708 | F8: 11.958707 | G8: 12.869706 | H8: 13.780704 | I8: 14.691703
B9: AGR | C9: 4.0977761 | D9: 4.3241331 | E9: 5.1406847 | F9: 5.8631577 | G9: 6.6527824 | H9: 7.7475745 | I9: 8.8593188
B10: TRS | C10: 34.547267 | D10: 35.452018 | E10: 39.96019 | F10: 43.890175 | G10: 47.806499 | H10: 52.12189 | I10: 56.170613
B13: Quote di input (Share-I FX) per settore - somma = 1
B14: Settore | C14: Commodity | D14: 2023 | E14: 2025 | F14: 2030 | G14: 2035 | H14: 2040 | I14: 2045 | J14: 2050 | K14: Tipo
B15: RES | C15: ELEC_LV_DIST | D15: 0.55979579 | E15: 0.58 | F15: 0.62 | G15: 0.66 | H15: 0.7 | I15: 0.74 | J15: 0.79 | K15: elettrico
B16: RES | C16: DIESEL | D16: 0.084263513 | E16: 0.02 | F16: 0 | G16: 0 | H16: 0 | I16: 0 | J16: 0 | K16: non elettrico
B17: RES | C17: OGL | D17: 0.26092633 | E17: 0.23 | F17: 0.2 | G17: 0.16 | H17: 0.12 | I17: 0.05 | J17: 0 | K17: non elettrico
B18: RES | C18: NLG | D18: 0.095014375 | E18: 0.17 | F18: 0.18 | G18: 0.18 | H18: 0.18 | I18: 0.21 | J18: 0.21 | K18: non elettrico
C19: Somma (controllo) | D19: =SUM(D15:D18) -> 1 | E19: =SUM(E15:E18) -> 1 | F19: =SUM(F15:F18) -> 1 | G19: =SUM(G15:G18) -> 1 | H19: =SUM(H15:H18) -> 1 | I19: =SUM(I15:I18) -> 1 | J19: =SUM(J15:J18) -> 1
B21: IND | C21: ELEC_LV_DIST | D21: 0.46304555 | E21: 0.41 | F21: 0.52 | G21: 0.62 | H21: 0.68 | I21: 0.75 | J21: 0.75 | K21: elettrico
B22: IND | C22: DIESEL | D22: 0.025717995 | E22: 0.02 | F22: 0 | G22: 0 | H22: 0 | I22: 0 | J22: 0 | K22: non elettrico
B23: IND | C23: GASOLINE | D23: 0.083096928 | E23: 0.09 | F23: 0.09 | G23: 0 | H23: 0 | I23: 0 | J23: 0 | K23: non elettrico
B24: IND | C24: OGL | D24: 0.083355984 | E24: 0.12 | F24: 0.1 | G24: 0.08 | H24: 0 | I24: 0 | J24: 0 | K24: non elettrico
B25: IND | C25: FUEL_OIL | D25: 0.099280949 | E25: 0.05 | F25: 0 | G25: 0 | H25: 0 | I25: 0 | J25: 0 | K25: non elettrico
B26: IND | C26: NLG | D26: 0 | E26: 0.03 | F26: 0.05 | G26: 0.1 | H26: 0.2 | I26: 0.21 | J26: 0.25 | K26: non elettrico
B27: IND | C27: SOLID | D27: 0.24550259 | E27: 0.28 | F27: 0.24 | G27: 0.2 | H27: 0.12 | I27: 0.04 | J27: 0 | K27: non elettrico
C28: Somma (controllo) | D28: =SUM(D21:D27) -> 1 | E28: =SUM(E21:E27) -> 1 | F28: =SUM(F21:F27) -> 1 | G28: =SUM(G21:G27) -> 1 | H28: =SUM(H21:H27) -> 1 | I28: =SUM(I21:I27) -> 1 | J28: =SUM(J21:J27) -> 1
B30: SER | C30: ELEC_LV_DIST | D30: 0.76479483 | E30: 0.73 | F30: 0.78 | G30: 0.84 | H30: 0.89 | I30: 0.91 | J30: 0.91 | K30: elettrico
B31: SER | C31: DIESEL | D31: 0.092402033 | E31: 0.09 | F31: 0.04 | G31: 0 | H31: 0 | I31: 0 | J31: 0 | K31: non elettrico
B32: SER | C32: OGL | D32: 0.14280314 | E32: 0.16 | F32: 0.12 | G32: 0.04 | H32: 0 | I32: 0 | J32: 0 | K32: non elettrico
B33: SER | C33: NLG | D33: 0 | E33: 0.02 | F33: 0.06 | G33: 0.12 | H33: 0.11 | I33: 0.09 | J33: 0.09 | K33: non elettrico
C34: Somma (controllo) | D34: =SUM(D30:D33) -> 1 | E34: =SUM(E30:E33) -> 1 | F34: =SUM(F30:F33) -> 1 | G34: =SUM(G30:G33) -> 1 | H34: =SUM(H30:H33) -> 1 | I34: =SUM(I30:I33) -> 1 | J34: =SUM(J30:J33) -> 1
B36: AGR | C36: DIESEL | D36: 0.20350307 | E36: 0.94 | F36: 0.8 | G36: 0.65 | H36: 0.49 | I36: 0.37 | J36: 0.2 | K36: non elettrico
B37: AGR | C37: ELEC_LV_DIST | D37: 0.79649693 | E37: 0.06 | F37: 0.11 | G37: 0.14 | H37: 0.21 | I37: 0.25 | J37: 0.3 | K37: elettrico
B38: AGR | C38: NLG | D38: 0 | E38: 0 | F38: 0.06 | G38: 0.12 | H38: 0.14 | I38: 0.19 | J38: 0.25 | K38: non elettrico
B39: AGR | C39: HYDROGEN_ENGINE | D39: 0 | E39: 0 | F39: 0.03 | G39: 0.09 | H39: 0.16 | I39: 0.19 | J39: 0.25 | K39: non elettrico
C40: Somma (controllo) | D40: =SUM(D36:D39) -> 1 | E40: =SUM(E36:E39) -> 1 | F40: =SUM(F36:F39) -> 1 | G40: =SUM(G36:G39) -> 1 | H40: =SUM(H36:H39) -> 1 | I40: =SUM(I36:I39) -> 1 | J40: =SUM(J36:J39) -> 1
B42: TRS | C42: GASOLINE | D42: 0.4173642 | E42: 0.38 | F42: 0.38 | G42: 0.34 | H42: 0.28 | I42: 0.2 | J42: 0.1 | K42: non elettrico
B43: TRS | C43: DIESEL | D43: 0.54999871 | E43: 0.59 | F43: 0.5 | G43: 0.45 | H43: 0.35 | I43: 0.27 | J43: 0.12 | K43: non elettrico
B44: TRS | C44: OGL | D44: 0.019202949 | E44: 0.02 | F44: 0.04 | G44: 0.05 | H44: 0.06 | I44: 0.06 | J44: 0.06 | K44: non elettrico
B45: TRS | C45: ELEC_LV_DIST | D45: 0.013434147 | E45: 0.01 | F45: 0.05 | G45: 0.07 | H45: 0.13 | I45: 0.21 | J45: 0.35 | K45: elettrico
B46: TRS | C46: NLG | D46: 0 | E46: 0 | F46: 0.02 | G46: 0.04 | H46: 0.1 | I46: 0.12 | J46: 0.18 | K46: non elettrico
B47: TRS | C47: HYDROGEN_ENGINE | D47: 0 | E47: 0 | F47: 0.01 | G47: 0.05 | H47: 0.08 | I47: 0.14 | J47: 0.19 | K47: non elettrico
...

Sheet SEC_Comm
B2: Commodity di domanda
B4: ~FI_Comm
B5: Csets | C5: CommName | D5: CommDesc | E5: Unit | F5: LimType | G5: CTSLvl | H5: PeakTS | I5: Ctype
B6: \I: Commodity Set | C6: Commodity Name | D6: Commodity Description | E6: Unit | F6: Sense of Balance Equation | G6: TimeSlice Level | H6: Peak Monitoring | I6: Electricity Indicator
B7: DEM | C7: DEM_ELC_RES | D7: Domanda elettrica finale - Residenziale | E7: PJ | G7: DAYNITE
B8: DEM | C8: DEM_FUEL_RES | D8: Domanda finale non elettrica - Residenziale | E8: PJ
B9: DEM | C9: DEM_ELC_IND | D9: Domanda elettrica finale - Industria | E9: PJ | G9: DAYNITE
B10: DEM | C10: DEM_FUEL_IND | D10: Domanda finale non elettrica - Industria | E10: PJ
B11: DEM | C11: DEM_ELC_SER | D11: Domanda elettrica finale - Servizi | E11: PJ | G11: DAYNITE
B12: DEM | C12: DEM_FUEL_SER | D12: Domanda finale non elettrica - Servizi | E12: PJ
B13: DEM | C13: DEM_ELC_AGR | D13: Domanda elettrica finale - Agricoltura | E13: PJ | G13: DAYNITE
B14: DEM | C14: DEM_FUEL_AGR | D14: Domanda finale non elettrica - Agricoltura | E14: PJ
B15: DEM | C15: DEM_ELC_TRS | D15: Domanda elettrica finale - Trasporti | E15: PJ | G15: DAYNITE
B16: DEM | C16: DEM_FUEL_TRS | D16: Domanda finale non elettrica - Trasporti | E16: PJ
B17: DEM | C17: DEM_H2_AGR | D17: Domanda finale idrogeno - Agricoltura | E17: PJ | G17: DAYNITE
B18: DEM | C18: DEM_H2_TRS | D18: Domanda finale idrogeno - Trasporti | E18: PJ | G18: DAYNITE

Sheet SEC_Processes
B2: Processi di domanda
B4: ~FI_Process
B5: Sets | C5: Region | D5: TechName | E5: TechDesc | F5: Tact | G5: Tcap | H5: Tslvl | I5: PrimaryCG | J5: Vintage
B6: \I: Process Set | C6: Region Name | D6: Technology Name | E6: Technology Description | F6: Activity Unit | G6: Capacity Unit | H6: TimeSlice Level | I6: Primary Commodity Group | J6: Vintage Tracking
B7: DMD | C7: SAR | D7: DMD_ELC_RES | E7: Domanda elettrica - Residenziale | F7: PJ | G7: PJa | H7: DAYNITE
B8: DMD | C8: SAR | D8: DMD_FUEL_RES | E8: Domanda non elettrica - Residenziale | F8: PJ | G8: PJa | H8: ANNUAL
B9: DMD | C9: SAR | D9: DMD_ELC_IND | E9: Domanda elettrica - Industria | F9: PJ | G9: PJa | H9: DAYNITE
B10: DMD | C10: SAR | D10: DMD_FUEL_IND | E10: Domanda non elettrica - Industria | F10: PJ | G10: PJa | H10: ANNUAL
B11: DMD | C11: SAR | D11: DMD_ELC_SER | E11: Domanda elettrica - Servizi | F11: PJ | G11: PJa | H11: DAYNITE
B12: DMD | C12: SAR | D12: DMD_FUEL_SER | E12: Domanda non elettrica - Servizi | F12: PJ | G12: PJa | H12: ANNUAL
B13: DMD | C13: SAR | D13: DMD_ELC_AGR | E13: Domanda elettrica - Agricoltura | F13: PJ | G13: PJa | H13: DAYNITE
B14: DMD | C14: SAR | D14: DMD_FUEL_AGR | E14: Domanda non elettrica - Agricoltura | F14: PJ | G14: PJa | H14: ANNUAL
B15: DMD | C15: SAR | D15: DMD_ELC_TRS | E15: Domanda elettrica - Trasporti | F15: PJ | G15: PJa | H15: DAYNITE
B16: DMD | C16: SAR | D16: DMD_FUEL_TRS | E16: Domanda non elettrica - Trasporti | F16: PJ | G16: PJa | H16: ANNUAL
B17: DMD | C17: SAR | D17: DMD_H2_AGR | E17: Domanda idrogeno - Agricoltura | F17: PJ | G17: PJa | H17: DAYNITE
B18: DMD | C18: SAR | D18: DMD_H2_TRS | E18: Domanda idrogeno - Trasporti | F18: PJ | G18: PJa | H18: DAYNITE

Sheet FINAL_DEMAND_PRC
B2: Tecnologie di domanda
B3: Quote non elettriche = quota combustibile / somma quote non elettriche ESCLUSO H2 (formule su INPUT). H2 ha processi dedicati DMD_H2_* (DAYNITE).
B4: ~FI_T
B5: TechName | C5: *TechDesc | D5: Comm-IN | E5: Comm-OUT | F5: Share-I~2023 | G5: Share-I~2025 | H5: Share-I~2030 | I5: Share-I~2035 | J5: Share-I~2040 | K5: Share-I~2045 | L5: Share-I~2050 | M5: EFF | N5: CAP2ACT
B6: \I: Technology Name | C6: Technology Description | D6: Commodity Input | E6: Commodity Output | F6: Quota input FX | G6: Quota input FX | H6: Quota input FX | I6: Quota input FX | J6: Quota input FX | K6: Quota input FX | L6: Quota input FX | M6: Efficiency | N6: Cap to Act
B7: DMD_ELC_RES | C7: Domanda elettrica - Residenziale | D7: ELEC_LV_DIST | E7: DEM_ELC_RES | M7: 1 | N7: 1
B8: DMD_FUEL_RES | C8: Domanda non elettrica - Residenziale | D8: DIESEL | E8: DEM_FUEL_RES | F8: =IFERROR(INPUT!D16/(INPUT!D16+INPUT!D17+INPUT!D18),0) -> 0.19141914 | G8: =IFERROR(INPUT!E16/(INPUT!E16+INPUT!E17+INPUT!E18),0) -> 0.047619048 | H8: =IFERROR(INPUT!F16/(INPUT!F16+INPUT!F17+INPUT!F18),0) -> 0 | I8: =IFERROR(INPUT!G16/(INPUT!G16+INPUT!G17+INPUT!G18),0) -> 0 | J8: =IFERROR(INPUT!H16/(INPUT!H16+INPUT!H17+INPUT!H18),0) -> 0 | K8: =IFERROR(INPUT!I16/(INPUT!I16+INPUT!I17+INPUT!I18),0) -> 0 | L8: =IFERROR(INPUT!J16/(INPUT!J16+INPUT!J17+INPUT!J18),0) -> 0 | M8: 1 | N8: 1
D9: OGL | E9: DEM_FUEL_RES | F9: =IFERROR(INPUT!D17/(INPUT!D16+INPUT!D17+INPUT!D18),0) -> 0.59273927 | G9: =IFERROR(INPUT!E17/(INPUT!E16+INPUT!E17+INPUT!E18),0) -> 0.54761905 | H9: =IFERROR(INPUT!F17/(INPUT!F16+INPUT!F17+INPUT!F18),0) -> 0.52631579 | I9: =IFERROR(INPUT!G17/(INPUT!G16+INPUT!G17+INPUT!G18),0) -> 0.47058824 | J9: =IFERROR(INPUT!H17/(INPUT!H16+INPUT!H17+INPUT!H18),0) -> 0.4 | K9: =IFERROR(INPUT!I17/(INPUT!I16+INPUT!I17+INPUT!I18),0) -> 0.19230769 | L9: =IFERROR(INPUT!J17/(INPUT!J16+INPUT!J17+INPUT!J18),0) -> 0 | M9: 1 | N9: 1
D10: NLG | E10: DEM_FUEL_RES | F10: =IFERROR(INPUT!D18/(INPUT!D16+INPUT!D17+INPUT!D18),0) -> 0.21584158 | G10: =IFERROR(INPUT!E18/(INPUT!E16+INPUT!E17+INPUT!E18),0) -> 0.4047619 | H10: =IFERROR(INPUT!F18/(INPUT!F16+INPUT!F17+INPUT!F18),0) -> 0.47368421 | I10: =IFERROR(INPUT!G18/(INPUT!G16+INPUT!G17+INPUT!G18),0) -> 0.52941176 | J10: =IFERROR(INPUT!H18/(INPUT!H16+INPUT!H17+INPUT!H18),0) -> 0.6 | K10: =IFERROR(INPUT!I18/(INPUT!I16+INPUT!I17+INPUT!I18),0) -> 0.80769231 | L10: =IFERROR(INPUT!J18/(INPUT!J16+INPUT!J17+INPUT!J18),0) -> 1 | M10: 1 | N10: 1
B11: DMD_ELC_IND | C11: Domanda elettrica - Industria | D11: ELEC_LV_DIST | E11: DEM_ELC_IND | M11: 1 | N11: 1
B12: DMD_FUEL_IND | C12: Domanda non elettrica - Industria | D12: DIESEL | E12: DEM_FUEL_IND | F12: =IFERROR(INPUT!D22/(INPUT!D22+INPUT!D23+INPUT!D24+INPUT!D25+INPUT!D26+INPUT!D27),0) -> 0.047896046 | G12: =IFERROR(INPUT!E22/(INPUT!E22+INPUT!E23+INPUT!E24+INPUT!E25+INPUT!E26+INPUT!E27),0) -> 0.033898305 | H12: =IFERROR(INPUT!F22/(INPUT!F22+INPUT!F23+INPUT!F24+INPUT!F25+INPUT!F26+INPUT!F27),0) -> 0 | I12: =IFERROR(INPUT!G22/(INPUT!G22+INPUT!G23+INPUT!G24+INPUT!G25+INPUT!G26+INPUT!G27),0) -> 0 | J12: =IFERROR(INPUT!H22/(INPUT!H22+INPUT!H23+INPUT!H24+INPUT!H25+INPUT!H26+INPUT!H27),0) -> 0 | K12: =IFERROR(INPUT!I22/(INPUT!I22+INPUT!I23+INPUT!I24+INPUT!I25+INPUT!I26+INPUT!I27),0) -> 0 | L12: =IFERROR(INPUT!J22/(INPUT!J22+INPUT!J23+INPUT!J24+INPUT!J25+INPUT!J26+INPUT!J27),0) -> 0 | M12: 1 | N12: 1
D13: GASOLINE | E13: DEM_FUEL_IND | F13: =IFERROR(INPUT!D23/(INPUT!D22+INPUT!D23+INPUT!D24+INPUT!D25+INPUT!D26+INPUT!D27),0) -> 0.15475601 | G13: =IFERROR(INPUT!E23/(INPUT!E22+INPUT!E23+INPUT!E24+INPUT!E25+INPUT!E26+INPUT!E27),0) -> 0.15254237 | H13: =IFERROR(INPUT!F23/(INPUT!F22+INPUT!F23+INPUT!F24+INPUT!F25+INPUT!F26+INPUT!F27),0) -> 0.1875 | I13: =IFERROR(INPUT!G23/(INPUT!G22+INPUT!G23+INPUT!G24+INPUT!G25+INPUT!G26+INPUT!G27),0) -> 0 | J13: =IFERROR(INPUT!H23/(INPUT!H22+INPUT!H23+INPUT!H24+INPUT!H25+INPUT!H26+INPUT!H27),0) -> 0 | K13: =IFERROR(INPUT!I23/(INPUT!I22+INPUT!I23+INPUT!I24+INPUT!I25+INPUT!I26+INPUT!I27),0) -> 0 | L13: =IFERROR(INPUT!J23/(INPUT!J22+INPUT!J23+INPUT!J24+INPUT!J25+INPUT!J26+INPUT!J27),0) -> 0 | M13: 1 | N13: 1
D14: OGL | E14: DEM_FUEL_IND | F14: =IFERROR(INPUT!D24/(INPUT!D22+INPUT!D23+INPUT!D24+INPUT!D25+INPUT!D26+INPUT!D27),0) -> 0.15523847 | G14: =IFERROR(INPUT!E24/(INPUT!E22+INPUT!E23+INPUT!E24+INPUT!E25+INPUT!E26+INPUT!E27),0) -> 0.20338983 | H14: =IFERROR(INPUT!F24/(INPUT!F22+INPUT!F23+INPUT!F24+INPUT!F25+INPUT!F26+INPUT!F27),0) -> 0.20833333 | I14: =IFERROR(INPUT!G24/(INPUT!G22+INPUT!G23+INPUT!G24+INPUT!G25+INPUT!G26+INPUT!G27),0) -> 0.21052632 | J14: =IFERROR(INPUT!H24/(INPUT!H22+INPUT!H23+INPUT!H24+INPUT!H25+INPUT!H26+INPUT!H27),0) -> 0 | K14: =IFERROR(INPUT!I24/(INPUT!I22+INPUT!I23+INPUT!I24+INPUT!I25+INPUT!I26+INPUT!I27),0) -> 0 | L14: =IFERROR(INPUT!J24/(INPUT!J22+INPUT!J23+INPUT!J24+INPUT!J25+INPUT!J26+INPUT!J27),0) -> 0 | M14: 1 | N14: 1
D15: FUEL_OIL | E15: DEM_FUEL_IND | F15: =IFERROR(INPUT!D25/(INPUT!D22+INPUT!D23+INPUT!D24+INPUT!D25+INPUT!D26+INPUT!D27),0) -> 0.18489641 | G15: =IFERROR(INPUT!E25/(INPUT!E22+INPUT!E23+INPUT!E24+INPUT!E25+INPUT!E26+INPUT!E27),0) -> 0.084745763 | H15: =IFERROR(INPUT!F25/(INPUT!F22+INPUT!F23+INPUT!F24+INPUT!F25+INPUT!F26+INPUT!F27),0) -> 0 | I15: =IFERROR(INPUT!G25/(INPUT!G22+INPUT!G23+INPUT!G24+INPUT!G25+INPUT!G26+INPUT!G27),0) -> 0 | J15: =IFERROR(INPUT!H25/(INPUT!H22+INPUT!H23+INPUT!H24+INPUT!H25+INPUT!H26+INPUT!H27),0) -> 0 | K15: =IFERROR(INPUT!I25/(INPUT!I22+INPUT!I23+INPUT!I24+INPUT!I25+INPUT!I26+INPUT!I27),0) -> 0 | L15: =IFERROR(INPUT!J25/(INPUT!J22+INPUT!J23+INPUT!J24+INPUT!J25+INPUT!J26+INPUT!J27),0) -> 0 | M15: 1 | N15: 1
D16: NLG | E16: DEM_FUEL_IND | F16: =IFERROR(INPUT!D26/(INPUT!D22+INPUT!D23+INPUT!D24+INPUT!D25+INPUT!D26+INPUT!D27),0) -> 0 | G16: =IFERROR(INPUT!E26/(INPUT!E22+INPUT!E23+INPUT!E24+INPUT!E25+INPUT!E26+INPUT!E27),0) -> 0.050847458 | H16: =IFERROR(INPUT!F26/(INPUT!F22+INPUT!F23+INPUT!F24+INPUT!F25+INPUT!F26+INPUT!F27),0) -> 0.10416667 | I16: =IFERROR(INPUT!G26/(INPUT!G22+INPUT!G23+INPUT!G24+INPUT!G25+INPUT!G26+INPUT!G27),0) -> 0.26315789 | J16: =IFERROR(INPUT!H26/(INPUT!H22+INPUT!H23+INPUT!H24+INPUT!H25+INPUT!H26+INPUT!H27),0) -> 0.625 | K16: =IFERROR(INPUT!I26/(INPUT!I22+INPUT!I23+INPUT!I24+INPUT!I25+INPUT!I26+INPUT!I27),0) -> 0.84 | L16: =IFERROR(INPUT!J26/(INPUT!J22+INPUT!J23+INPUT!J24+INPUT!J25+INPUT!J26+INPUT!J27),0) -> 1 | M16: 1 | N16: 1
D17: SOLID | E17: DEM_FUEL_IND | F17: =IFERROR(INPUT!D27/(INPUT!D22+INPUT!D23+INPUT!D24+INPUT!D25+INPUT!D26+INPUT!D27),0) -> 0.45721307 | G17: =IFERROR(INPUT!E27/(INPUT!E22+INPUT!E23+INPUT!E24+INPUT!E25+INPUT!E26+INPUT!E27),0) -> 0.47457627 | H17: =IFERROR(INPUT!F27/(INPUT!F22+INPUT!F23+INPUT!F24+INPUT!F25+INPUT!F26+INPUT!F27),0) -> 0.5 | I17: =IFERROR(INPUT!G27/(INPUT!G22+INPUT!G23+INPUT!G24+INPUT!G25+INPUT!G26+INPUT!G27),0) -> 0.52631579 | J17: =IFERROR(INPUT!H27/(INPUT!H22+INPUT!H23+INPUT!H24+INPUT!H25+INPUT!H26+INPUT!H27),0) -> 0.375 | K17: =IFERROR(INPUT!I27/(INPUT!I22+INPUT!I23+INPUT!I24+INPUT!I25+INPUT!I26+INPUT!I27),0) -> 0.16 | L17: =IFERROR(INPUT!J27/(INPUT!J22+INPUT!J23+INPUT!J24+INPUT!J25+INPUT!J26+INPUT!J27),0) -> 0 | M17: 1 | N17: 1
B18: DMD_ELC_SER | C18: Domanda elettrica - Servizi | D18: ELEC_LV_DIST | E18: DEM_ELC_SER | M18: 1 | N18: 1
B19: DMD_FUEL_SER | C19: Domanda non elettrica - Servizi | D19: DIESEL | E19: DEM_FUEL_SER | F19: =IFERROR(INPUT!D31/(INPUT!D31+INPUT!D32+INPUT!D33),0) -> 0.39285714 | G19: =IFERROR(INPUT!E31/(INPUT!E31+INPUT!E32+INPUT!E33),0) -> 0.33333333 | H19: =IFERROR(INPUT!F31/(INPUT!F31+INPUT!F32+INPUT!F33),0) -> 0.18181818 | I19: =IFERROR(INPUT!G31/(INPUT!G31+INPUT!G32+INPUT!G33),0) -> 0 | J19: =IFERROR(INPUT!H31/(INPUT!H31+INPUT!H32+INPUT!H33),0) -> 0 | K19: =IFERROR(INPUT!I31/(INPUT!I31+INPUT!I32+INPUT!I33),0) -> 0 | L19: =IFERROR(INPUT!J31/(INPUT!J31+INPUT!J32+INPUT!J33),0) -> 0 | M19: 1 | N19: 1
D20: OGL | E20: DEM_FUEL_SER | F20: =IFERROR(INPUT!D32/(INPUT!D31+INPUT!D32+INPUT!D33),0) -> 0.60714286 | G20: =IFERROR(INPUT!E32/(INPUT!E31+INPUT!E32+INPUT!E33),0) -> 0.59259259 | H20: =IFERROR(INPUT!F32/(INPUT!F31+INPUT!F32+INPUT!F33),0) -> 0.54545455 | I20: =IFERROR(INPUT!G32/(INPUT!G31+INPUT!G32+INPUT!G33),0) -> 0.25 | J20: =IFERROR(INPUT!H32/(INPUT!H31+INPUT!H32+INPUT!H33),0) -> 0 | K20: =IFERROR(INPUT!I32/(INPUT!I31+INPUT!I32+INPUT!I33),0) -> 0 | L20: =IFERROR(INPUT!J32/(INPUT!J31+INPUT!J32+INPUT!J33),0) -> 0 | M20: 1 | N20: 1
D21: NLG | E21: DEM_FUEL_SER | F21: =IFERROR(INPUT!D33/(INPUT!D31+INPUT!D32+INPUT!D33),0) -> 0 | G21: =IFERROR(INPUT!E33/(INPUT!E31+INPUT!E32+INPUT!E33),0) -> 0.074074074 | H21: =IFERROR(INPUT!F33/(INPUT!F31+INPUT!F32+INPUT!F33),0) -> 0.27272727 | I21: =IFERROR(INPUT!G33/(INPUT!G31+INPUT!G32+INPUT!G33),0) -> 0.75 | J21: =IFERROR(INPUT!H33/(INPUT!H31+INPUT!H32+INPUT!H33),0) -> 1 | K21: =IFERROR(INPUT!I33/(INPUT!I31+INPUT!I32+INPUT!I33),0) -> 1 | L21: =IFERROR(INPUT!J33/(INPUT!J31+INPUT!J32+INPUT!J33),0) -> 1 | M21: 1 | N21: 1
B22: DMD_ELC_AGR | C22: Domanda elettrica - Agricoltura | D22: ELEC_LV_DIST | E22: DEM_ELC_AGR | M22: 1 | N22: 1
B23: DMD_FUEL_AGR | C23: Domanda non elettrica - Agricoltura | D23: DIESEL | E23: DEM_FUEL_AGR | F23: =IFERROR(INPUT!D36/(INPUT!D36+INPUT!D38),0) -> 1 | G23: =IFERROR(INPUT!E36/(INPUT!E36+INPUT!E38),0) -> 1 | H23: =IFERROR(INPUT!F36/(INPUT!F36+INPUT!F38),0) -> 0.93023256 | I23: =IFERROR(INPUT!G36/(INPUT!G36+INPUT!G38),0) -> 0.84415584 | J23: =IFERROR(INPUT!H36/(INPUT!H36+INPUT!H38),0) -> 0.77777778 | K23: =IFERROR(INPUT!I36/(INPUT!I36+INPUT!I38),0) -> 0.66071429 | L23: =IFERROR(INPUT!J36/(INPUT!J36+INPUT!J38),0) -> 0.44444444 | M23: 1 | N23: 1
D24: NLG | E24: DEM_FUEL_AGR | F24: =IFERROR(INPUT!D38/(INPUT!D36+INPUT!D38),0) -> 0 | G24: =IFERROR(INPUT!E38/(INPUT!E36+INPUT!E38),0) -> 0 | H24: =IFERROR(INPUT!F38/(INPUT!F36+INPUT!F38),0) -> 0.069767442 | I24: =IFERROR(INPUT!G38/(INPUT!G36+INPUT!G38),0) -> 0.15584416 | J24: =IFERROR(INPUT!H38/(INPUT!H36+INPUT!H38),0) -> 0.22222222 | K24: =IFERROR(INPUT!I38/(INPUT!I36+INPUT!I38),0) -> 0.33928571 | L24: =IFERROR(INPUT!J38/(INPUT!J36+INPUT!J38),0) -> 0.55555556 | M24: 1 | N24: 1
B25: DMD_H2_AGR | C25: Domanda idrogeno - Agricoltura | D25: HYDROGEN_ENGINE | E25: DEM_H2_AGR | M25: 1 | N25: 1
B26: DMD_ELC_TRS | C26: Domanda elettrica - Trasporti | D26: ELEC_LV_DIST | E26: DEM_ELC_TRS | M26: 1 | N26: 1
B27: DMD_FUEL_TRS | C27: Domanda non elettrica - Trasporti | D27: GASOLINE | E27: DEM_FUEL_TRS | F27: =IFERROR(INPUT!D42/(INPUT!D42+INPUT!D43+INPUT!D44+INPUT!D46),0) -> 0.42304748 | G27: =IFERROR(INPUT!E42/(INPUT!E42+INPUT!E43+INPUT!E44+INPUT!E46),0) -> 0.38383838 | H27: =IFERROR(INPUT!F42/(INPUT!F42+INPUT!F43+INPUT!F44+INPUT!F46),0) -> 0.40425532 | I27: =IFERROR(INPUT!G42/(INPUT!G42+INPUT!G43+INPUT!G44+INPUT!G46),0) -> 0.38636364 | J27: =IFERROR(INPUT!H42/(INPUT!H42+INPUT!H43+INPUT!H44+INPUT!H46),0) -> 0.35443038 | K27: =IFERROR(INPUT!I42/(INPUT!I42+INPUT!I43+INPUT!I44+INPUT!I46),0) -> 0.30769231 | L27: =IFERROR(INPUT!J42/(INPUT!J42+INPUT!J43+INPUT!J44+INPUT!J46),0) -> 0.2173913 | M27: 1 | N27: 1
D28: DIESEL | E28: DEM_FUEL_TRS | F28: =IFERROR(INPUT!D43/(INPUT!D42+INPUT!D43+INPUT!D44+INPUT!D46),0) -> 0.55748808 | G28: =IFERROR(INPUT!E43/(INPUT!E42+INPUT!E43+INPUT!E44+INPUT!E46),0) -> 0.5959596 | H28: =IFERROR(INPUT!F43/(INPUT!F42+INPUT!F43+INPUT!F44+INPUT!F46),0) -> 0.53191489 | I28: =IFERROR(INPUT!G43/(INPUT!G42+INPUT!G43+INPUT!G44+INPUT!G46),0) -> 0.51136364 | J28: =IFERROR(INPUT!H43/(INPUT!H42+INPUT!H43+INPUT!H44+INPUT!H46),0) -> 0.44303797 | K28: =IFERROR(INPUT!I43/(INPUT!I42+INPUT!I43+INPUT!I44+INPUT!I46),0) -> 0.41538462 | L28: =IFERROR(INPUT!J43/(INPUT!J42+INPUT!J43+INPUT!J44+INPUT!J46),0) -> 0.26086957 | M28: 1 | N28: 1
D29: OGL | E29: DEM_FUEL_TRS | F29: =IFERROR(INPUT!D44/(INPUT!D42+INPUT!D43+INPUT!D44+INPUT!D46),0) -> 0.019464437 | G29: =IFERROR(INPUT!E44/(INPUT!E42+INPUT!E43+INPUT!E44+INPUT!E46),0) -> 0.02020202 | H29: =IFERROR(INPUT!F44/(INPUT!F42+INPUT!F43+INPUT!F44+INPUT!F46),0) -> 0.042553191 | I29: =IFERROR(INPUT!G44/(INPUT!G42+INPUT!G43+INPUT!G44+INPUT!G46),0) -> 0.056818182 | J29: =IFERROR(INPUT!H44/(INPUT!H42+INPUT!H43+INPUT!H44+INPUT!H46),0) -> 0.075949367 | K29: =IFERROR(INPUT!I44/(INPUT!I42+INPUT!I43+INPUT!I44+INPUT!I46),0) -> 0.092307692 | L29: =IFERROR(INPUT!J44/(INPUT!J42+INPUT!J43+INPUT!J44+INPUT!J46),0) -> 0.13043478 | M29: 1 | N29: 1
D30: NLG | E30: DEM_FUEL_TRS | F30: =IFERROR(INPUT!D46/(INPUT!D42+INPUT!D43+INPUT!D44+INPUT!D46),0) -> 0 | G30: =IFERROR(INPUT!E46/(INPUT!E42+INPUT!E43+INPUT!E44+INPUT!E46),0) -> 0 | H30: =IFERROR(INPUT!F46/(INPUT!F42+INPUT!F43+INPUT!F44+INPUT!F46),0) -> 0.021276596 | I30: =IFERROR(INPUT!G46/(INPUT!G42+INPUT!G43+INPUT!G44+INPUT!G46),0) -> 0.045454545 | J30: =IFERROR(INPUT!H46/(INPUT!H42+INPUT!H43+INPUT!H44+INPUT!H46),0) -> 0.12658228 | K30: =IFERROR(INPUT!I46/(INPUT!I42+INPUT!I43+INPUT!I44+INPUT!I46),0) -> 0.18461538 | L30: =IFERROR(INPUT!J46/(INPUT!J42+INPUT!J43+INPUT!J44+INPUT!J46),0) -> 0.39130435 | M30: 1 | N30: 1
B31: DMD_H2_TRS | C31: Domanda idrogeno - Trasporti | D31: HYDROGEN_ENGINE | E31: DEM_H2_TRS | M31: 1 | N31: 1

Sheet DEMAND
B2: Domanda di servizio
B3: DEM_ELC = totale x quota elettrica ; DEM_FUEL = totale x quote non elettriche escluso H2 ; DEM_H2 = totale x quota H2
B4: ~FI_T:DEMAND
B5: CommName | C5: 2023 | D5: 2025 | E5: 2030 | F5: 2035 | G5: 2040 | H5: 2045 | I5: 2050
B6: \I: Commodity Name | C6: Annual Demand [PJ/a] | D6: Annual Demand [PJ/a] | E6: Annual Demand [PJ/a] | F6: Annual Demand [PJ/a] | G6: Annual Demand [PJ/a] | H6: Annual Demand [PJ/a] | I6: Annual Demand [PJ/a]
B7: DEM_ELC_RES | C7: =INPUT!C6*INPUT!D15 -> 8.0531232 | D7: =INPUT!D6*INPUT!E15 -> 7.96934 | E7: =INPUT!E6*INPUT!F15 -> 8.3625709 | F7: =INPUT!F6*INPUT!G15 -> 8.983916 | G7: =INPUT!G6*INPUT!H15 -> 10.223787 | H7: =INPUT!H6*INPUT!I15 -> 11.935968 | I7: =INPUT!I6*INPUT!J15 -> 13.946631
B8: DEM_FUEL_RES | C8: =INPUT!C6*(INPUT!D16+INPUT!D17+INPUT!D18) -> 6.3327 | D8: =INPUT!D6*(INPUT!E16+INPUT!E17+INPUT!E18) -> 5.7709014 | E8: =INPUT!E6*(INPUT!F16+INPUT!F17+INPUT!F18) -> 5.1254467 | F8: =INPUT!F6*(INPUT!G16+INPUT!G17+INPUT!G18) -> 4.6280779 | G8: =INPUT!G6*(INPUT!H16+INPUT!H17+INPUT!H18) -> 4.3816231 | H8: =INPUT!H6*(INPUT!I16+INPUT!I17+INPUT!I18) -> 4.1937185 | I8: =INPUT!I6*(INPUT!J16+INPUT!J17+INPUT!J18) -> 3.7073322
B9: DEM_ELC_IND | C9: =INPUT!C7*INPUT!D21 -> 10.851987 | D9: =INPUT!D7*INPUT!E21 -> 10.064493 | E9: =INPUT!E7*INPUT!F21 -> 13.73165 | F9: =INPUT!F7*INPUT!G21 -> 17.525227 | G9: =INPUT!G7*INPUT!H21 -> 20.73993 | H9: =INPUT!H7*INPUT!I21 -> 26.870055 | I9: =INPUT!I7*INPUT!J21 -> 31.222771
B10: DEM_FUEL_IND | C10: =INPUT!C7*(INPUT!D22+INPUT!D23+INPUT!D24+INPUT!D25+INPUT!D26+INPUT!D27) -> 12.584125 | D10: =INPUT!D7*(INPUT!E22+INPUT!E23+INPUT!E24+INPUT!E25+INPUT!E26+INPUT!E27) -> 14.483051 | E10: =INPUT!E7*(INPUT!F22+INPUT!F23+INPUT!F24+INPUT!F25+INPUT!F26+INPUT!F27) -> 12.675369 | F10: =INPUT!F7*(INPUT!G22+INPUT!G23+INPUT!G24+INPUT!G25+INPUT!G26+INPUT!G27) -> 10.741268 | G10: =INPUT!G7*(INPUT!H22+INPUT!H23+INPUT!H24+INPUT!H25+INPUT!H26+INPUT!H27) -> 9.7599669 | H10: =INPUT!H7*(INPUT!I22+INPUT!I23+INPUT!I24+INPUT!I25+INPUT!I26+INPUT!I27) -> 8.9566851 | I10: =INPUT!I7*(INPUT!J22+INPUT!J23+INPUT!J24+INPUT!J25+INPUT!J26+INPUT!J27) -> 10.40759
B11: DEM_ELC_SER | C11: =INPUT!C8*INPUT!D30 -> 7.611362 | D11: =INPUT!D8*INPUT!E30 -> 7.3997976 | E11: =INPUT!E8*INPUT!F30 -> 8.6172121 | F11: =INPUT!F8*INPUT!G30 -> 10.045314 | G11: =INPUT!G8*INPUT!H30 -> 11.454038 | H11: =INPUT!H8*INPUT!I30 -> 12.540441 | I11: =INPUT!I8*INPUT!J30 -> 13.36945
B12: DEM_FUEL_SER | C12: =INPUT!C8*(INPUT!D31+INPUT!D32+INPUT!D33) -> 2.3408 | D12: =INPUT!D8*(INPUT!E31+INPUT!E32+INPUT!E33) -> 2.7369114 | E12: =INPUT!E8*(INPUT!F31+INPUT!F32+INPUT!F33) -> 2.4304957 | F12: =INPUT!F8*(INPUT!G31+INPUT!G32+INPUT!G33) -> 1.9133931 | G12: =INPUT!G8*(INPUT!H31+INPUT!H32+INPUT!H33) -> 1.4156676 | H12: =INPUT!H8*(INPUT!I31+INPUT!I32+INPUT!I33) -> 1.2402634 | I12: =INPUT!I8*(INPUT!J31+INPUT!J32+INPUT!J33) -> 1.3222533
B13: DEM_ELC_AGR | C13: =INPUT!C9*INPUT!D37 -> 3.2638661 | D13: =INPUT!D9*INPUT!E37 -> 0.25944799 | E13: =INPUT!E9*INPUT!F37 -> 0.56547531 | F13: =INPUT!F9*INPUT!G37 -> 0.82084208 | G13: =INPUT!G9*INPUT!H37 -> 1.3970843 | H13: =INPUT!H9*INPUT!I37 -> 1.9368936 | I13: =INPUT!I9*INPUT!J37 -> 2.6577956
B14: DEM_FUEL_AGR | C14: =INPUT!C9*(INPUT!D36+INPUT!D38) -> 0.83391 | D14: =INPUT!D9*(INPUT!E36+INPUT!E38) -> 4.0646851 | E14: =INPUT!E9*(INPUT!F36+INPUT!F38) -> 4.4209888 | F14: =INPUT!F9*(INPUT!G36+INPUT!G38) -> 4.5146315 | G14: =INPUT!G9*(INPUT!H36+INPUT!H38) -> 4.1912529 | H14: =INPUT!H9*(INPUT!I36+INPUT!I38) -> 4.3386417 | I14: =INPUT!I9*(INPUT!J36+INPUT!J38) -> 3.9866935
B15: DEM_ELC_TRS | C15: =INPUT!C10*INPUT!D45 -> 0.46411307 | D15: =INPUT!D10*INPUT!E45 -> 0.35452018 | E15: =INPUT!E10*INPUT!F45 -> 1.9980095 | F15: =INPUT!F10*INPUT!G45 -> 3.0723122 | G15: =INPUT!G10*INPUT!H45 -> 6.2148449 | H15: =INPUT!H10*INPUT!I45 -> 10.945597 | I15: =INPUT!I10*INPUT!J45 -> 19.659715
B16: DEM_FUEL_TRS | C16: =INPUT!C10*(INPUT!D42+INPUT!D43+INPUT!D44+INPUT!D46) -> 34.083154 | D16: =INPUT!D10*(INPUT!E42+INPUT!E43+INPUT!E44+INPUT!E46) -> 35.097498 | E16: =INPUT!E10*(INPUT!F42+INPUT!F43+INPUT!F44+INPUT!F46) -> 37.562579 | F16: =INPUT!F10*(INPUT!G42+INPUT!G43+INPUT!G44+INPUT!G46) -> 38.623354 | G16: =INPUT!G10*(INPUT!H42+INPUT!H43+INPUT!H44+INPUT!H46) -> 37.767134 | H16: =INPUT!H10*(INPUT!I42+INPUT!I43+INPUT!I44+INPUT!I46) -> 33.879228 | I16: =INPUT!I10*(INPUT!J42+INPUT!J43+INPUT!J44+INPUT!J46) -> 25.838482
B17: DEM_H2_AGR | C17: =INPUT!C9*INPUT!D39 -> 0 | D17: =INPUT!D9*INPUT!E39 -> 0 | E17: =INPUT!E9*INPUT!F39 -> 0.15422054 | F17: =INPUT!F9*INPUT!G39 -> 0.5276842 | G17: =INPUT!G9*INPUT!H39 -> 1.0644452 | H17: =INPUT!H9*INPUT!I39 -> 1.4720392 | I17: =INPUT!I9*INPUT!J39 -> 2.2148297
B18: DEM_H2_TRS | C18: =INPUT!C10*INPUT!D47 -> 0 | D18: =INPUT!D10*INPUT!E47 -> 0 | E18: =INPUT!E10*INPUT!F47 -> 0.3996019 | F18: =INPUT!F10*INPUT!G47 -> 2.1945087 | G18: =INPUT!G10*INPUT!H47 -> 3.8245199 | H18: =INPUT!H10*INPUT!I47 -> 7.2970646 | I18: =INPUT!I10*INPUT!J47 -> 10.672417
B20: Controllo: ELC+FUEL(+H2) - totale (deve essere 0)
B21: RES | C21: =C7+C8-INPUT!C6 -> 0 | D21: =D7+D8-INPUT!D6 -> 0 | E21: =E7+E8-INPUT!E6 -> 0 | F21: =F7+F8-INPUT!F6 -> 0 | G21: =G7+G8-INPUT!G6 -> 0 | H21: =H7+H8-INPUT!H6 -> 0 | I21: =I7+I8-INPUT!I6 -> 0
B22: IND | C22: =C9+C10-INPUT!C7 -> 0 | D22: =D9+D10-INPUT!D7 -> 0 | E22: =E9+E10-INPUT!E7 -> 0 | F22: =F9+F10-INPUT!F7 -> 0 | G22: =G9+G10-INPUT!G7 -> 0 | H22: =H9+H10-INPUT!H7 -> 0 | I22: =I9+I10-INPUT!I7 -> 0
B23: SER | C23: =C11+C12-INPUT!C8 -> 0 | D23: =D11+D12-INPUT!D8 -> 0 | E23: =E11+E12-INPUT!E8 -> 0 | F23: =F11+F12-INPUT!F8 -> 0 | G23: =G11+G12-INPUT!G8 -> 0 | H23: =H11+H12-INPUT!H8 -> 0 | I23: =I11+I12-INPUT!I8 -> 0
B24: AGR | C24: =C13+C14+C17-INPUT!C9 -> 0 | D24: =D13+D14+D17-INPUT!D9 -> 0 | E24: =E13+E14+E17-INPUT!E9 -> 0 | F24: =F13+F14+F17-INPUT!F9 -> 0 | G24: =G13+G14+G17-INPUT!G9 -> 0 | H24: =H13+H14+H17-INPUT!H9 -> 0 | I24: =I13+I14+I17-INPUT!I9 -> 0
B25: TRS | C25: =C15+C16+C18-INPUT!C10 -> 0 | D25: =D15+D16+D18-INPUT!D10 -> 0 | E25: =E15+E16+E18-INPUT!E10 -> 0 | F25: =F15+F16+F18-INPUT!F10 -> 0 | G25: =G15+G16+G18-INPUT!G10 -> 0 | H25: =H15+H16+H18-INPUT!H10 -> 0 | I25: =I15+I16+I18-INPUT!I10 -> 0

Sheet EMI
B2: Fattori di emissione per combustibile [kt/PJ]
B4: ~PRCCOMEMI
B5: TechName | C5: CommName | D5: DIESEL | E5: OGL | F5: NLG | G5: GASOLINE | H5: FUEL_OIL | I5: SOLID
B6: \I: Technology Name | C6: Commodity Name (Pollutant) | D6: kt/PJ | E6: kt/PJ | F6: kt/PJ | G6: kt/PJ | H6: kt/PJ | I6: kt/PJ
B7: DMD_FUEL_RES | C7: CO2 | D7: =INPUT!B52 -> 74.1 | E7: =INPUT!C52 -> 63.1 | F7: =INPUT!D52 -> 56.1 | G7: =INPUT!E52 -> 69.3 | H7: =INPUT!F52 -> 77.4 | I7: =INPUT!G52 -> 95
B8: DMD_FUEL_IND | C8: CO2 | D8: =INPUT!B52 -> 74.1 | E8: =INPUT!C52 -> 63.1 | F8: =INPUT!D52 -> 56.1 | G8: =INPUT!E52 -> 69.3 | H8: =INPUT!F52 -> 77.4 | I8: =INPUT!G52 -> 95
B9: DMD_FUEL_SER | C9: CO2 | D9: =INPUT!B52 -> 74.1 | E9: =INPUT!C52 -> 63.1 | F9: =INPUT!D52 -> 56.1 | G9: =INPUT!E52 -> 69.3 | H9: =INPUT!F52 -> 77.4 | I9: =INPUT!G52 -> 95
B10: DMD_FUEL_AGR | C10: CO2 | D10: =INPUT!B52 -> 74.1 | E10: =INPUT!C52 -> 63.1 | F10: =INPUT!D52 -> 56.1 | G10: =INPUT!E52 -> 69.3 | H10: =INPUT!F52 -> 77.4 | I10: =INPUT!G52 -> 95
B11: DMD_FUEL_TRS | C11: CO2 | D11: =INPUT!B52 -> 74.1 | E11: =INPUT!C52 -> 63.1 | F11: =INPUT!D52 -> 56.1 | G11: =INPUT!E52 -> 69.3 | H11: =INPUT!F52 -> 77.4 | I11: =INPUT!G52 -> 95
